Workbook
Name Goal: 'By Teacher'!$B$4

Sheet By Teacher
A1: SAINTS RUN WILD • BY TEACHER
A3: Raised | B3: Goal | C3: % of goal | D3: To go | E3: Students donated
A4: =SUM(Donations!$D:$D) | B4: 65000 | C4: =IF(B4>0,A4/B4,0) | D4: =MAX(0,B4-A4) | E4: =IFERROR(COUNTIF(Students!$E:$E,"Yes")/(COUNTA(Students!$A:$A)-1),0)
A5: =IF(COUNTIF(Donations!$G:$G,"NOT ON LIST")=0,"✔ Every donation matches a student","⚠ "&COUNTIF(Donations!$G:$G,"NOT ON LIST")&" donation(s) ("&TEXT(SUMIFS(Donations!$D:$D,Donations!$G:$G,"NOT ON LIST"),"$#,##0")&") have a student not on the Students list (red rows on Donations)")
A7: Teacher (type once) | B7: Grade | C7: Students | D7: Donated | E7: Participation | F7: Total $ | G7: Rank
A8: Ms. Alvarez | B8: =IF(A8="","",IFERROR(INDEX(Students!$C:$C,MATCH(A8,Students!$B:$B,0))&"","")) | C8: =IF(A8="","",COUNTIF(Students!$B:$B,A8)) | D8: =IF(A8="","",COUNTIFS(Students!$B:$B,A8,Students!$D:$D,">0")) | E8: =IF(OR(A8="",N(C8)=0),"",D8/C8) | F8: =IF(A8="","",SUMIFS(Donations!$D:$D,Donations!$H:$H,A8)) | G8: =IF(A8="","",COUNTIF($F$8:$F$37,">"&F8)+1)
A9: Mrs. Bennett | B9: =IF(A9="","",IFERROR(INDEX(Students!$C:$C,MATCH(A9,Students!$B:$B,0))&"","")) | C9: =IF(A9="","",COUNTIF(Students!$B:$B,A9)) | D9: =IF(A9="","",COUNTIFS(Students!$B:$B,A9,Students!$D:$D,">0")) | E9: =IF(OR(A9="",N(C9)=0),"",D9/C9) | F9: =IF(A9="","",SUMIFS(Donations!$D:$D,Donations!$H:$H,A9)) | G9: =IF(A9="","",COUNTIF($F$8:$F$37,">"&F9)+1)
A10: Mr. Carter | B10: =IF(A10="","",IFERROR(INDEX(Students!$C:$C,MATCH(A10,Students!$B:$B,0))&"","")) | C10: =IF(A10="","",COUNTIF(Students!$B:$B,A10)) | D10: =IF(A10="","",COUNTIFS(Students!$B:$B,A10,Students!$D:$D,">0")) | E10: =IF(OR(A10="",N(C10)=0),"",D10/C10) | F10: =IF(A10="","",SUMIFS(Donations!$D:$D,Donations!$H:$H,A10)) | G10: =IF(A10="","",COUNTIF($F$8:$F$37,">"&F10)+1)
A11: Mrs. Dominguez | B11: =IF(A11="","",IFERROR(INDEX(Students!$C:$C,MATCH(A11,Students!$B:$B,0))&"","")) | C11: =IF(A11="","",COUNTIF(Students!$B:$B,A11)) | D11: =IF(A11="","",COUNTIFS(Students!$B:$B,A11,Students!$D:$D,">0")) | E11: =IF(OR(A11="",N(C11)=0),"",D11/C11) | F11: =IF(A11="","",SUMIFS(Donations!$D:$D,Donations!$H:$H,A11)) | G11: =IF(A11="","",COUNTIF($F$8:$F$37,">"&F11)+1)
A12: Ms. Ellison | B12: =IF(A12="","",IFERROR(INDEX(Students!$C:$C,MATCH(A12,Students!$B:$B,0))&"","")) | C12: =IF(A12="","",COUNTIF(Students!$B:$B,A12)) | D12: =IF(A12="","",COUNTIFS(Students!$B:$B,A12,Students!$D:$D,">0")) | E12: =IF(OR(A12="",N(C12)=0),"",D12/C12) | F12: =IF(A12="","",SUMIFS(Donations!$D:$D,Donations!$H:$H,A12)) | G12: =IF(A12="","",COUNTIF($F$8:$F$37,">"&F12)+1)
A13: Mrs. Fischer | B13: =IF(A13="","",IFERROR(INDEX(Students!$C:$C,MATCH(A13,Students!$B:$B,0))&"","")) | C13: =IF(A13="","",COUNTIF(Students!$B:$B,A13)) | D13: =IF(A13="","",COUNTIFS(Students!$B:$B,A13,Students!$D:$D,">0")) | E13: =IF(OR(A13="",N(C13)=0),"",D13/C13) | F13: =IF(A13="","",SUMIFS(Donations!$D:$D,Donations!$H:$H,A13)) | G13: =IF(A13="","",COUNTIF($F$8:$F$37,">"&F13)+1)
A14: Mr. Galloway | B14: =IF(A14="","",IFERROR(INDEX(Students!$C:$C,MATCH(A14,Students!$B:$B,0))&"","")) | C14: =IF(A14="","",COUNTIF(Students!$B:$B,A14)) | D14: =IF(A14="","",COUNTIFS(Students!$B:$B,A14,Students!$D:$D,">0")) | E14: =IF(OR(A14="",N(C14)=0),"",D14/C14) | F14: =IF(A14="","",SUMIFS(Donations!$D:$D,Donations!$H:$H,A14)) | G14: =IF(A14="","",COUNTIF($F$8:$F$37,">"&F14)+1)
A15: Mrs. Hayes | B15: =IF(A15="","",IFERROR(INDEX(Students!$C:$C,MATCH(A15,Students!$B:$B,0))&"","")) | C15: =IF(A15="","",COUNTIF(Students!$B:$B,A15)) | D15: =IF(A15="","",COUNTIFS(Students!$B:$B,A15,Students!$D:$D,">0")) | E15: =IF(OR(A15="",N(C15)=0),"",D15/C15) | F15: =IF(A15="","",SUMIFS(Donations!$D:$D,Donations!$H:$H,A15)) | G15: =IF(A15="","",COUNTIF($F$8:$F$37,">"&F15)+1)
A16: Ms. Ingram | B16: =IF(A16="","",IFERROR(INDEX(Students!$C:$C,MATCH(A16,Students!$B:$B,0))&"","")) | C16: =IF(A16="","",COUNTIF(Students!$B:$B,A16)) | D16: =IF(A16="","",COUNTIFS(Students!$B:$B,A16,Students!$D:$D,">0")) | E16: =IF(OR(A16="",N(C16)=0),"",D16/C16) | F16: =IF(A16="","",SUMIFS(Donations!$D:$D,Donations!$H:$H,A16)) | G16: =IF(A16="","",COUNTIF($F$8:$F$37,">"&F16)+1)
A17: Mrs. Jensen | B17: =IF(A17="","",IFERROR(INDEX(Students!$C:$C,MATCH(A17,Students!$B:$B,0))&"","")) | C17: =IF(A17="","",COUNTIF(Students!$B:$B,A17)) | D17: =IF(A17="","",COUNTIFS(Students!$B:$B,A17,Students!$D:$D,">0")) | E17: =IF(OR(A17="",N(C17)=0),"",D17/C17) | F17: =IF(A17="","",SUMIFS(Donations!$D:$D,Donations!$H:$H,A17)) | G17: =IF(A17="","",COUNTIF($F$8:$F$37,">"&F17)+1)
A18: Mr. Kowalski | B18: =IF(A18="","",IFERROR(INDEX(Students!$C:$C,MATCH(A18,Students!$B:$B,0))&"","")) | C18: =IF(A18="","",COUNTIF(Students!$B:$B,A18)) | D18: =IF(A18="","",COUNTIFS(Students!$B:$B,A18,Students!$D:$D,">0")) | E18: =IF(OR(A18="",N(C18)=0),"",D18/C18) | F18: =IF(A18="","",SUMIFS(Donations!$D:$D,Donations!$H:$H,A18)) | G18: =IF(A18="","",COUNTIF($F$8:$F$37,">"&F18)+1)
A19: Mrs. Lindqvist | B19: =IF(A19="","",IFERROR(INDEX(Students!$C:$C,MATCH(A19,Students!$B:$B,0))&"","")) | C19: =IF(A19="","",COUNTIF(Students!$B:$B,A19)) | D19: =IF(A19="","",COUNTIFS(Students!$B:$B,A19,Students!$D:$D,">0")) | E19: =IF(OR(A19="",N(C19)=0),"",D19/C19) | F19: =IF(A19="","",SUMIFS(Donations!$D:$D,Donations!$H:$H,A19)) | G19: =IF(A19="","",COUNTIF($F$8:$F$37,">"&F19)+1)
... A29: Mrs. Valdez | B29: =IF(A29="","",IFERROR(INDEX(Students!$C:$C,MATCH(A29,Students!$B:$B,0))&"","")) | C29: =IF(A29="","",COUNTIF(Students!$B:$B,A29)) | D29: =IF(A29="","",COUNTIFS(Students!$B:$B,A29,Students!$D:$D,">0")) | E29: =IF(OR(A29="",N(C29)=0),"",D29/C29) | F29: =IF(A29="","",SUMIFS(Donations!$D:$D,Donations!$H:$H,A29)) | G29: =IF(A29="","",COUNTIF($F$8:$F$37,">"&F29)+1)
B30: =IF(A30="","",IFERROR(INDEX(Students!$C:$C,MATCH(A30,Students!$B:$B,0))&"","")) | C30: =IF(A30="","",COUNTIF(Students!$B:$B,A30)) | D30: =IF(A30="","",COUNTIFS(Students!$B:$B,A30,Students!$D:$D,">0")) | E30: =IF(OR(A30="",N(C30)=0),"",D30/C30) | F30: =IF(A30="","",SUMIFS(Donations!$D:$D,Donations!$H:$H,A30)) | G30: =IF(A30="","",COUNTIF($F$8:$F$37,">"&F30)+1)
B31: =IF(A31="","",IFERROR(INDEX(Students!$C:$C,MATCH(A31,Students!$B:$B,0))&"","")) | C31: =IF(A31="","",COUNTIF(Students!$B:$B,A31)) | D31: =IF(A31="","",COUNTIFS(Students!$B:$B,A31,Students!$D:$D,">0")) | E31: =IF(OR(A31="",N(C31)=0),"",D31/C31) | F31: =IF(A31="","",SUMIFS(Donations!$D:$D,Donations!$H:$H,A31)) | G31: =IF(A31="","",COUNTIF($F$8:$F$37,">"&F31)+1)
B32: =IF(A32="","",IFERROR(INDEX(Students!$C:$C,MATCH(A32,Students!$B:$B,0))&"","")) | C32: =IF(A32="","",COUNTIF(Students!$B:$B,A32)) | D32: =IF(A32="","",COUNTIFS(Students!$B:$B,A32,Students!$D:$D,">0")) | E32: =IF(OR(A32="",N(C32)=0),"",D32/C32) | F32: =IF(A32="","",SUMIFS(Donations!$D:$D,Donations!$H:$H,A32)) | G32: =IF(A32="","",COUNTIF($F$8:$F$37,">"&F32)+1)
B33: =IF(A33="","",IFERROR(INDEX(Students!$C:$C,MATCH(A33,Students!$B:$B,0))&"","")) | C33: =IF(A33="","",COUNTIF(Students!$B:$B,A33)) | D33: =IF(A33="","",COUNTIFS(Students!$B:$B,A33,Students!$D:$D,">0")) | E33: =IF(OR(A33="",N(C33)=0),"",D33/C33) | F33: =IF(A33="","",SUMIFS(Donations!$D:$D,Donations!$H:$H,A33)) | G33: =IF(A33="","",COUNTIF($F$8:$F$37,">"&F33)+1)
B34: =IF(A34="","",IFERROR(INDEX(Students!$C:$C,MATCH(A34,Students!$B:$B,0))&"","")) | C34: =IF(A34="","",COUNTIF(Students!$B:$B,A34)) | D34: =IF(A34="","",COUNTIFS(Students!$B:$B,A34,Students!$D:$D,">0")) | E34: =IF(OR(A34="",N(C34)=0),"",D34/C34) | F34: =IF(A34="","",SUMIFS(Donations!$D:$D,Donations!$H:$H,A34)) | G34: =IF(A34="","",COUNTIF($F$8:$F$37,">"&F34)+1)
B35: =IF(A35="","",IFERROR(INDEX(Students!$C:$C,MATCH(A35,Students!$B:$B,0))&"","")) | C35: =IF(A35="","",COUNTIF(Students!$B:$B,A35)) | D35: =IF(A35="","",COUNTIFS(Students!$B:$B,A35,Students!$D:$D,">0")) | E35: =IF(OR(A35="",N(C35)=0),"",D35/C35) | F35: =IF(A35="","",SUMIFS(Donations!$D:$D,Donations!$H:$H,A35)) | G35: =IF(A35="","",COUNTIF($F$8:$F$37,">"&F35)+1)
B36: =IF(A36="","",IFERROR(INDEX(Students!$C:$C,MATCH(A36,Students!$B:$B,0))&"","")) | C36: =IF(A36="","",COUNTIF(Students!$B:$B,A36)) | D36: =IF(A36="","",COUNTIFS(Students!$B:$B,A36,Students!$D:$D,">0")) | E36: =IF(OR(A36="",N(C36)=0),"",D36/C36) | F36: =IF(A36="","",SUMIFS(Donations!$D:$D,Donations!$H:$H,A36)) | G36: =IF(A36="","",COUNTIF($F$8:$F$37,">"&F36)+1)
B37: =IF(A37="","",IFERROR(INDEX(Students!$C:$C,MATCH(A37,Students!$B:$B,0))&"","")) | C37: =IF(A37="","",COUNTIF(Students!$B:$B,A37)) | D37: =IF(A37="","",COUNTIFS(Students!$B:$B,A37,Students!$D:$D,">0")) | E37: =IF(OR(A37="",N(C37)=0),"",D37/C37) | F37: =IF(A37="","",SUMIFS(Donations!$D:$D,Donations!$H:$H,A37)) | G37: =IF(A37="","",COUNTIF($F$8:$F$37,">"&F37)+1)
A39: Grade | C39: Students | D39: Donated | E39: Participation | F39: Total $ | G39: Rank
A40: Grade P3 | B40: P3 | C40: =COUNTIF(Students!$C:$C,B40) | D40: =COUNTIFS(Students!$C:$C,B40,Students!$D:$D,">0") | E40: =IF(C40=0,"",D40/C40) | F40: =SUMIFS(Donations!$D:$D,Donations!$I:$I,B40) | G40: =COUNTIF($F$40:$F$50,">"&F40)+1
A41: Grade P4 | B41: P4 | C41: =COUNTIF(Students!$C:$C,B41) | D41: =COUNTIFS(Students!$C:$C,B41,Students!$D:$D,">0") | E41: =IF(C41=0,"",D41/C41) | F41: =SUMIFS(Donations!$D:$D,Donations!$I:$I,B41) | G41: =COUNTIF($F$40:$F$50,">"&F41)+1
A42: Grade K | B42: K | C42: =COUNTIF(Students!$C:$C,B42) | D42: =COUNTIFS(Students!$C:$C,B42,Students!$D:$D,">0") | E42: =IF(C42=0,"",D42/C42) | F42: =SUMIFS(Donations!$D:$D,Donations!$I:$I,B42) | G42: =COUNTIF($F$40:$F$50,">"&F42)+1
A43: Grade 1 | B43: 1 | C43: =COUNTIF(Students!$C:$C,B43) | D43: =COUNTIFS(Students!$C:$C,B43,Students!$D:$D,">0") | E43: =IF(C43=0,"",D43/C43) | F43: =SUMIFS(Donations!$D:$D,Donations!$I:$I,B43) | G43: =COUNTIF($F$40:$F$50,">"&F43)+1
A44: Grade 2 | B44: 2 | C44: =COUNTIF(Students!$C:$C,B44) | D44: =COUNTIFS(Students!$C:$C,B44,Students!$D:$D,">0") | E44: =IF(C44=0,"",D44/C44) | F44: =SUMIFS(Donations!$D:$D,Donations!$I:$I,B44) | G44: =COUNTIF($F$40:$F$50,">"&F44)+1
A45: Grade 3 | B45: 3 | C45: =COUNTIF(Students!$C:$C,B45) | D45: =COUNTIFS(Students!$C:$C,B45,Students!$D:$D,">0") | E45: =IF(C45=0,"",D45/C45) | F45: =SUMIFS(Donations!$D:$D,Donations!$I:$I,B45) | G45: =COUNTIF($F$40:$F$50,">"&F45)+1
A46: Grade 4 | B46: 4 | C46: =COUNTIF(Students!$C:$C,B46) | D46: =COUNTIFS(Students!$C:$C,B46,Students!$D:$D,">0") | E46: =IF(C46=0,"",D46/C46) | F46: =SUMIFS(Donations!$D:$D,Donations!$I:$I,B46) | G46: =COUNTIF($F$40:$F$50,">"&F46)+1
A47: Grade 5 | B47: 5 | C47: =COUNTIF(Students!$C:$C,B47) | D47: =COUNTIFS(Students!$C:$C,B47,Students!$D:$D,">0") | E47: =IF(C47=0,"",D47/C47) | F47: =SUMIFS(Donations!$D:$D,Donations!$I:$I,B47) | G47: =COUNTIF($F$40:$F$50,">"&F47)+1
A48: Grade 6 | B48: 6 | C48: =COUNTIF(Students!$C:$C,B48) | D48: =COUNTIFS(Students!$C:$C,B48,Students!$D:$D,">0") | E48: =IF(C48=0,"",D48/C48) | F48: =SUMIFS(Donations!$D:$D,Donations!$I:$I,B48) | G48: =COUNTIF($F$40:$F$50,">"&F48)+1
A49: Grade 7 | B49: 7 | C49: =COUNTIF(Students!$C:$C,B49) | D49: =COUNTIFS(Students!$C:$C,B49,Students!$D:$D,">0") | E49: =IF(C49=0,"",D49/C49) | F49: =SUMIFS(Donations!$D:$D,Donations!$I:$I,B49) | G49: =COUNTIF($F$40:$F$50,">"&F49)+1
A50: Grade 8 | B50: 8 | C50: =COUNTIF(Students!$C:$C,B50) | D50: =COUNTIFS(Students!$C:$C,B50,Students!$D:$D,">0") | E50: =IF(C50=0,"",D50/C50) | F50: =SUMIFS(Donations!$D:$D,Donations!$I:$I,B50) | G50: =COUNTIF($F$40:$F$50,">"&F50)+1

Sheet By Day
A1: SAINTS RUN WILD • BY DAY
A3: First day: | B3: 46325
A5: Date | B5: $ raised | C5: Gifts | D5: Running total | E5: % of goal
A6: =$B$3+0 | B6: =SUMIFS(Donations!$D:$D,Donations!$F:$F,A6) | C6: =COUNTIFS(Donations!$F:$F,A6) | D6: =SUMIFS(Donations!$D:$D,Donations!$F:$F,"<="&A6) | E6: =IF(Goal>0,D6/Goal,0)
A7: =$B$3+1 | B7: =SUMIFS(Donations!$D:$D,Donations!$F:$F,A7) | C7: =COUNTIFS(Donations!$F:$F,A7) | D7: =SUMIFS(Donations!$D:$D,Donations!$F:$F,"<="&A7) | E7: =IF(Goal>0,D7/Goal,0)
A8: =$B$3+2 | B8: =SUMIFS(Donations!$D:$D,Donations!$F:$F,A8) | C8: =COUNTIFS(Donations!$F:$F,A8) | D8: =SUMIFS(Donations!$D:$D,Donations!$F:$F,"<="&A8) | E8: =IF(Goal>0,D8/Goal,0)
A9: =$B$3+3 | B9: =SUMIFS(Donations!$D:$D,Donations!$F:$F,A9) | C9: =COUNTIFS(Donations!$F:$F,A9) | D9: =SUMIFS(Donations!$D:$D,Donations!$F:$F,"<="&A9) | E9: =IF(Goal>0,D9/Goal,0)
A10: =$B$3+4 | B10: =SUMIFS(Donations!$D:$D,Donations!$F:$F,A10) | C10: =COUNTIFS(Donations!$F:$F,A10) | D10: =SUMIFS(Donations!$D:$D,Donations!$F:$F,"<="&A10) | E10: =IF(Goal>0,D10/Goal,0)
A11: =$B$3+5 | B11: =SUMIFS(Donations!$D:$D,Donations!$F:$F,A11) | C11: =COUNTIFS(Donations!$F:$F,A11) | D11: =SUMIFS(Donations!$D:$D,Donations!$F:$F,"<="&A11) | E11: =IF(Goal>0,D11/Goal,0)
A12: =$B$3+6 | B12: =SUMIFS(Donations!$D:$D,Donations!$F:$F,A12) | C12: =COUNTIFS(Donations!$F:$F,A12) | D12: =SUMIFS(Donations!$D:$D,Donations!$F:$F,"<="&A12) | E12: =IF(Goal>0,D12/Goal,0)
A13: =$B$3+7 | B13: =SUMIFS(Donations!$D:$D,Donations!$F:$F,A13) | C13: =COUNTIFS(Donations!$F:$F,A13) | D13: =SUMIFS(Donations!$D:$D,Donations!$F:$F,"<="&A13) | E13: =IF(Goal>0,D13/Goal,0)
A14: =$B$3+8 | B14: =SUMIFS(Donations!$D:$D,Donations!$F:$F,A14) | C14: =COUNTIFS(Donations!$F:$F,A14) | D14: =SUMIFS(Donations!$D:$D,Donations!$F:$F,"<="&A14) | E14: =IF(Goal>0,D14/Goal,0)
A15: =$B$3+9 | B15: =SUMIFS(Donations!$D:$D,Donations!$F:$F,A15) | C15: =COUNTIFS(Donations!$F:$F,A15) | D15: =SUMIFS(Donations!$D:$D,Donations!$F:$F,"<="&A15) | E15: =IF(Goal>0,D15/Goal,0)
A16: =$B$3+10 | B16: =SUMIFS(Donations!$D:$D,Donations!$F:$F,A16) | C16: =COUNTIFS(Donations!$F:$F,A16) | D16: =SUMIFS(Donations!$D:$D,Donations!$F:$F,"<="&A16) | E16: =IF(Goal>0,D16/Goal,0)
A17: =$B$3+11 | B17: =SUMIFS(Donations!$D:$D,Donations!$F:$F,A17) | C17: =COUNTIFS(Donations!$F:$F,A17) | D17: =SUMIFS(Donations!$D:$D,Donations!$F:$F,"<="&A17) | E17: =IF(Goal>0,D17/Goal,0)
A18: =$B$3+12 | B18: =SUMIFS(Donations!$D:$D,Donations!$F:$F,A18) | C18: =COUNTIFS(Donations!$F:$F,A18) | D18: =SUMIFS(Donations!$D:$D,Donations!$F:$F,"<="&A18) | E18: =IF(Goal>0,D18/Goal,0)
A19: =$B$3+13 | B19: =SUMIFS(Donations!$D:$D,Donations!$F:$F,A19) | C19: =COUNTIFS(Donations!$F:$F,A19) | D19: =SUMIFS(Donations!$D:$D,Donations!$F:$F,"<="&A19) | E19: =IF(Goal>0,D19/Goal,0)
A20: =$B$3+14 | B20: =SUMIFS(Donations!$D:$D,Donations!$F:$F,A20) | C20: =COUNTIFS(Donations!$F:$F,A20) | D20: =SUMIFS(Donations!$D:$D,Donations!$F:$F,"<="&A20) | E20: =IF(Goal>0,D20/Goal,0)
A21: TOTAL | B21: =SUM(B6:B20) | C21: =SUM(C6:C20)
A22: Gifts dated outside these days are in the running total only.

Sheet Daily Challenges
A1: SAINTS RUN WILD • DAILY CHALLENGES
A2: Dates and Min $ / Target are editable. Winners update automatically.
A4: Challenge | B4: Day | C4: Start | D4: End | E4: Reward | F4: Winner / result | G4: Min $ / Target
A5: Kickoff Weekend Challenge | B5: Fri | C5: 46325 | D5: 46327 | E5: Top class in every grade wins | F5: =IF(COUNTIF($D$54:$D$64,">0")=0,"No gifts yet","See GRADE SCORES below")
A6: Monday Blues | B6: Mon | C6: 46328 | D6: 46328 | E6: Turn the blues into green | F6: —
A7: $20 Tuesday | B7: Tue | C7: 46329 | D7: 46329 | E7: Silly string the teacher | F7: =IF(N(MAX($G$21:$G$50))<=0,"No gifts yet",INDEX($A$21:$A$50,MATCH(MAX($G$21:$G$50),$G$21:$G$50,0))&IF(COUNTIF($G$21:$G$50,MAX($G$21:$G$50))>1," (tie)","")&" — "&TEXT(MAX($G$21:$G$50),"0%")) | G7: 20
A8: Wild Card Wednesday | B8: Wed | C8: 46330 | D8: 46330 | E8: 10 Wild Card winners | F8: =COUNTIF(Students!$G:$G,">0")&" eligible: draw "&N(G8)&" (Students col G > $0)" | G8: 10
A9: Classroom Showdown | B9: Thu | C9: 46331 | D9: 46331 | E9: Doughnuts + coffee for the teacher | F9: =IF(N(MAX($H$21:$H$50))<=0,"No gifts yet",INDEX($A$21:$A$50,MATCH(MAX($H$21:$H$50),$H$21:$H$50,0))&IF(COUNTIF($H$21:$H$50,MAX($H$21:$H$50))>1," (tie)","")&" — "&TEXT(MAX($H$21:$H$50),"0%"))
A10: Weekend Challenge | B10: Fri | C10: 46332 | D10: 46334 | E10: Top fundraiser in every class pies a teacher | F10: =IF(COUNTIF($F$21:$F$50,">0")=0,"No gifts yet","See CLASS SCORES below")
A11: Grade vs. Grade | B11: Mon | C11: 46335 | D11: 46335 | E11: Pizza lunch for the winning grade | F11: =IF(MAX($C$54:$C$64)<=0,"No gifts yet","Grade "&INDEX($A$54:$A$64,MATCH(MAX($C$54:$C$64),$C$54:$C$64,0))&IF(COUNTIF($C$54:$C$64,MAX($C$54:$C$64))>1," (tie)","")&" — "&TEXT(MAX($C$54:$C$64),"$#,##0"))
A12: 50% Participation | B12: Tue | C12: 46336 | D12: 46336 | E12: Mrs. Rhodes & Mrs. Sites dress up | F12: =IF(IFERROR(COUNTIF(Students!$J:$J,">0")/(COUNTA(Students!$A:$A)-1),0)>=N(G12),"HIT! ","Not yet: ")&TEXT(IFERROR(COUNTIF(Students!$J:$J,">0")/(COUNTA(Students!$A:$A)-1),0),"0%")&" of "&TEXT(N(G12),"0%") | G12: 0.5
A13: Veterans Day (no school) | B13: Wed | C13: 46337 | D13: 46337 | E13: Thank you, Veterans! | F13: —
A14: Mystery Day | B14: Thu | C14: 46338 | D14: 46338 | E14: The final WILD push | F14: —
A15: Run Wild Fun Run! | B15: Fri | C15: 46339 | D15: 46339 | E15: Celebrate! | F15: —
A16: Ultimate Wild Goal | B16: All | C16: 46325 | D16: 46339 | E16: Father Peter & Mrs. Rhodes get SLIMED | F16: =IF(SUMIFS(Donations!$D:$D,Donations!$F:$F,"<="&D16)>=N(G16),"HIT! ","Not yet: ")&TEXT(SUMIFS(Donations!$D:$D,Donations!$F:$F,"<="&D16),"$#,##0")&" of "&TEXT(N(G16),"$#,##0") | G16: 60000
A19: CLASS SCORES
A20: Teacher | B20: Grade | C20: Students | D20: Kickoff Weekend Challenge $ | E20: Weekend Challenge: top student | F20: Weekend Challenge $ | G20: $20 Tuesday % | H20: Classroom Showdown %
A21: =IF('By Teacher'!A8="","",'By Teacher'!A8) | B21: =IF(A21="","",'By Teacher'!B8) | C21: =IF(A21="","",'By Teacher'!C8) | D21: =IF(A21="","",SUMIFS(Donations!$D:$D,Donations!$H:$H,A21,Donations!$F:$F,">="&'Daily Challenges'!$C$5,Donations!$F:$F,"<="&'Daily Challenges'!$D$5)) | E21: {=IF(A21="","",IF(N(F21)<=0,"—",INDEX(Students!$A$2:$A$601,MATCH(1,(Students!$B$2:$B$601=A21)*(Students!$I$2:$I$601=F21),0))&IF(COUNTIFS(Students!$B$2:$B$601,A21,Students!$I$2:$I$601,F21)>1," (tie)","")))} | F21: =IF(A21="","",_xlfn.MAXIFS(Students!$I$2:$I$601,Students!$B$2:$B$601,A21)) | G21: =IF(OR(A21="",N(C21)=0),"",COUNTIFS(Students!$B:$B,A21,Students!$F:$F,">="&MAX(0.01,N('Daily Challenges'!$G$7)))/C21) | H21: =IF(OR(A21="",N(C21)=0),"",COUNTIFS(Students!$B:$B,A21,Students!$H:$H,">0")/C21)
A22: =IF('By Teacher'!A9="","",'By Teacher'!A9) | B22: =IF(A22="","",'By Teacher'!B9) | C22: =IF(A22="","",'By Teacher'!C9) | D22: =IF(A22="","",SUMIFS(Donations!$D:$D,Donations!$H:$H,A22,Donations!$F:$F,">="&'Daily Challenges'!$C$5,Donations!$F:$F,"<="&'Daily Challenges'!$D$5)) | E22: {=IF(A22="","",IF(N(F22)<=0,"—",INDEX(Students!$A$2:$A$601,MATCH(1,(Students!$B$2:$B$601=A22)*(Students!$I$2:$I$601=F22),0))&IF(COUNTIFS(Students!$B$2:$B$601,A22,Students!$I$2:$I$601,F22)>1," (tie)","")))} | F22: =IF(A22="","",_xlfn.MAXIFS(Students!$I$2:$I$601,Students!$B$2:$B$601,A22)) | G22: =IF(OR(A22="",N(C22)=0),"",COUNTIFS(Students!$B:$B,A22,Students!$F:$F,">="&MAX(0.01,N('Daily Challenges'!$G$7)))/C22) | H22: =IF(OR(A22="",N(C22)=0),"",COUNTIFS(Students!$B:$B,A22,Students!$H:$H,">0")/C22)
A23: =IF('By Teacher'!A10="","",'By Teacher'!A10) | B23: =IF(A23="","",'By Teacher'!B10) | C23: =IF(A23="","",'By Teacher'!C10) | D23: =IF(A23="","",SUMIFS(Donations!$D:$D,Donations!$H:$H,A23,Donations!$F:$F,">="&'Daily Challenges'!$C$5,Donations!$F:$F,"<="&'Daily Challenges'!$D$5)) | E23: {=IF(A23="","",IF(N(F23)<=0,"—",INDEX(Students!$A$2:$A$601,MATCH(1,(Students!$B$2:$B$601=A23)*(Students!$I$2:$I$601=F23),0))&IF(COUNTIFS(Students!$B$2:$B$601,A23,Students!$I$2:$I$601,F23)>1," (tie)","")))} | F23: =IF(A23="","",_xlfn.MAXIFS(Students!$I$2:$I$601,Students!$B$2:$B$601,A23)) | G23: =IF(OR(A23="",N(C23)=0),"",COUNTIFS(Students!$B:$B,A23,Students!$F:$F,">="&MAX(0.01,N('Daily Challenges'!$G$7)))/C23) | H23: =IF(OR(A23="",N(C23)=0),"",COUNTIFS(Students!$B:$B,A23,Students!$H:$H,">0")/C23)
A24: =IF('By Teacher'!A11="","",'By Teacher'!A11) | B24: =IF(A24="","",'By Teacher'!B11) | C24: =IF(A24="","",'By Teacher'!C11) | D24: =IF(A24="","",SUMIFS(Donations!$D:$D,Donations!$H:$H,A24,Donations!$F:$F,">="&'Daily Challenges'!$C$5,Donations!$F:$F,"<="&'Daily Challenges'!$D$5)) | E24: {=IF(A24="","",IF(N(F24)<=0,"—",INDEX(Students!$A$2:$A$601,MATCH(1,(Students!$B$2:$B$601=A24)*(Students!$I$2:$I$601=F24),0))&IF(COUNTIFS(Students!$B$2:$B$601,A24,Students!$I$2:$I$601,F24)>1," (tie)","")))} | F24: =IF(A24="","",_xlfn.MAXIFS(Students!$I$2:$I$601,Students!$B$2:$B$601,A24)) | G24: =IF(OR(A24="",N(C24)=0),"",COUNTIFS(Students!$B:$B,A24,Students!$F:$F,">="&MAX(0.01,N('Daily Challenges'!$G$7)))/C24) | H24: =IF(OR(A24="",N(C24)=0),"",COUNTIFS(Students!$B:$B,A24,Students!$H:$H,">0")/C24)
A25: =IF('By Teacher'!A12="","",'By Teacher'!A12) | B25: =IF(A25="","",'By Teacher'!B12) | C25: =IF(A25="","",'By Teacher'!C12) | D25: =IF(A25="","",SUMIFS(Donations!$D:$D,Donations!$H:$H,A25,Donations!$F:$F,">="&'Daily Challenges'!$C$5,Donations!$F:$F,"<="&'Daily Challenges'!$D$5)) | E25: {=IF(A25="","",IF(N(F25)<=0,"—",INDEX(Students!$A$2:$A$601,MATCH(1,(Students!$B$2:$B$601=A25)*(Students!$I$2:$I$601=F25),0))&IF(COUNTIFS(Students!$B$2:$B$601,A25,Students!$I$2:$I$601,F25)>1," (tie)","")))} | F25: =IF(A25="","",_xlfn.MAXIFS(Students!$I$2:$I$601,Students!$B$2:$B$601,A25)) | G25: =IF(OR(A25="",N(C25)=0),"",COUNTIFS(Students!$B:$B,A25,Students!$F:$F,">="&MAX(0.01,N('Daily Challenges'!$G$7)))/C25) | H25: =IF(OR(A25="",N(C25)=0),"",COUNTIFS(Students!$B:$B,A25,Students!$H:$H,">0")/C25)
A26: =IF('By Teacher'!A13="","",'By Teacher'!A13) | B26: =IF(A26="","",'By Teacher'!B13) | C26: =IF(A26="","",'By Teacher'!C13) | D26: =IF(A26="","",SUMIFS(Donations!$D:$D,Donations!$H:$H,A26,Donations!$F:$F,">="&'Daily Challenges'!$C$5,Donations!$F:$F,"<="&'Daily Challenges'!$D$5)) | E26: {=IF(A26="","",IF(N(F26)<=0,"—",INDEX(Students!$A$2:$A$601,MATCH(1,(Students!$B$2:$B$601=A26)*(Students!$I$2:$I$601=F26),0))&IF(COUNTIFS(Students!$B$2:$B$601,A26,Students!$I$2:$I$601,F26)>1," (tie)","")))} | F26: =IF(A26="","",_xlfn.MAXIFS(Students!$I$2:$I$601,Students!$B$2:$B$601,A26)) | G26: =IF(OR(A26="",N(C26)=0),"",COUNTIFS(Students!$B:$B,A26,Students!$F:$F,">="&MAX(0.01,N('Daily Challenges'!$G$7)))/C26) | H26: =IF(OR(A26="",N(C26)=0),"",COUNTIFS(Students!$B:$B,A26,Students!$H:$H,">0")/C26)
A27: =IF('By Teacher'!A14="","",'By Teacher'!A14) | B27: =IF(A27="","",'By Teacher'!B14) | C27: =IF(A27="","",'By Teacher'!C14) | D27: =IF(A27="","",SUMIFS(Donations!$D:$D,Donations!$H:$H,A27,Donations!$F:$F,">="&'Daily Challenges'!$C$5,Donations!$F:$F,"<="&'Daily Challenges'!$D$5)) | E27: {=IF(A27="","",IF(N(F27)<=0,"—",INDEX(Students!$A$2:$A$601,MATCH(1,(Students!$B$2:$B$601=A27)*(Students!$I$2:$I$601=F27),0))&IF(COUNTIFS(Students!$B$2:$B$601,A27,Students!$I$2:$I$601,F27)>1," (tie)","")))} | F27: =IF(A27="","",_xlfn.MAXIFS(Students!$I$2:$I$601,Students!$B$2:$B$601,A27)) | G27: =IF(OR(A27="",N(C27)=0),"",COUNTIFS(Students!$B:$B,A27,Students!$F:$F,">="&MAX(0.01,N('Daily Challenges'!$G$7)))/C27) | H27: =IF(OR(A27="",N(C27)=0),"",COUNTIFS(Students!$B:$B,A27,Students!$H:$H,">0")/C27)
A28: =IF('By Teacher'!A15="","",'By Teacher'!A15) | B28: =IF(A28="","",'By Teacher'!B15) | C28: =IF(A28="","",'By Teacher'!C15) | D28: =IF(A28="","",SUMIFS(Donations!$D:$D,Donations!$H:$H,A28,Donations!$F:$F,">="&'Daily Challenges'!$C$5,Donations!$F:$F,"<="&'Daily Challenges'!$D$5)) | E28: {=IF(A28="","",IF(N(F28)<=0,"—",INDEX(Students!$A$2:$A$601,MATCH(1,(Students!$B$2:$B$601=A28)*(Students!$I$2:$I$601=F28),0))&IF(COUNTIFS(Students!$B$2:$B$601,A28,Students!$I$2:$I$601,F28)>1," (tie)","")))} | F28: =IF(A28="","",_xlfn.MAXIFS(Students!$I$2:$I$601,Students!$B$2:$B$601,A28)) | G28: =IF(OR(A28="",N(C28)=0),"",COUNTIFS(Students!$B:$B,A28,Students!$F:$F,">="&MAX(0.01,N('Daily Challenges'!$G$7)))/C28) | H28: =IF(OR(A28="",N(C28)=0),"",COUNTIFS(Students!$B:$B,A28,Students!$H:$H,">0")/C28)
A29: =IF('By Teacher'!A16="","",'By Teacher'!A16) | B29: =IF(A29="","",'By Teacher'!B16) | C29: =IF(A29="","",'By Teacher'!C16) | D29: =IF(A29="","",SUMIFS(Donations!$D:$D,Donations!$H:$H,A29,Donations!$F:$F,">="&'Daily Challenges'!$C$5,Donations!$F:$F,"<="&'Daily Challenges'!$D$5)) | E29: {=IF(A29="","",IF(N(F29)<=0,"—",INDEX(Students!$A$2:$A$601,MATCH(1,(Students!$B$2:$B$601=A29)*(Students!$I$2:$I$601=F29),0))&IF(COUNTIFS(Students!$B$2:$B$601,A29,Students!$I$2:$I$601,F29)>1," (tie)","")))} | F29: =IF(A29="","",_xlfn.MAXIFS(Students!$I$2:$I$601,Students!$B$2:$B$601,A29)) | G29: =IF(OR(A29="",N(C29)=0),"",COUNTIFS(Students!$B:$B,A29,Students!$F:$F,">="&MAX(0.01,N('Daily Challenges'!$G$7)))/C29) | H29: =IF(OR(A29="",N(C29)=0),"",COUNTIFS(Students!$B:$B,A29,Students!$H:$H,">0")/C29)
A30: =IF('By Teacher'!A17="","",'By Teacher'!A17) | B30: =IF(A30="","",'By Teacher'!B17) | C30: =IF(A30="","",'By Teacher'!C17) | D30: =IF(A30="","",SUMIFS(Donations!$D:$D,Donations!$H:$H,A30,Donations!$F:$F,">="&'Daily Challenges'!$C$5,Donations!$F:$F,"<="&'Daily Challenges'!$D$5)) | E30: {=IF(A30="","",IF(N(F30)<=0,"—",INDEX(Students!$A$2:$A$601,MATCH(1,(Students!$B$2:$B$601=A30)*(Students!$I$2:$I$601=F30),0))&IF(COUNTIFS(Students!$B$2:$B$601,A30,Students!$I$2:$I$601,F30)>1," (tie)","")))} | F30: =IF(A30="","",_xlfn.MAXIFS(Students!$I$2:$I$601,Students!$B$2:$B$601,A30)) | G30: =IF(OR(A30="",N(C30)=0),"",COUNTIFS(Students!$B:$B,A30,Students!$F:$F,">="&MAX(0.01,N('Daily Challenges'!$G$7)))/C30) | H30: =IF(OR(A30="",N(C30)=0),"",COUNTIFS(Students!$B:$B,A30,Students!$H:$H,">0")/C30)
A31: =IF('By Teacher'!A18="","",'By Teacher'!A18) | B31: =IF(A31="","",'By Teacher'!B18) | C31: =IF(A31="","",'By Teacher'!C18) | D31: =IF(A31="","",SUMIFS(Donations!$D:$D,Donations!$H:$H,A31,Donations!$F:$F,">="&'Daily Challenges'!$C$5,Donations!$F:$F,"<="&'Daily Challenges'!$D$5)) | E31: {=IF(A31="","",IF(N(F31)<=0,"—",INDEX(Students!$A$2:$A$601,MATCH(1,(Students!$B$2:$B$601=A31)*(Students!$I$2:$I$601=F31),0))&IF(COUNTIFS(Students!$B$2:$B$601,A31,Students!$I$2:$I$601,F31)>1," (tie)","")))} | F31: =IF(A31="","",_xlfn.MAXIFS(Students!$I$2:$I$601,Students!$B$2:$B$601,A31)) | G31: =IF(OR(A31="",N(C31)=0),"",COUNTIFS(Students!$B:$B,A31,Students!$F:$F,">="&MAX(0.01,N('Daily Challenges'!$G$7)))/C31) | H31: =IF(OR(A31="",N(C31)=0),"",COUNTIFS(Students!$B:$B,A31,Students!$H:$H,">0")/C31)
A32: =IF('By Teacher'!A19="","",'By Teacher'!A19) | B32: =IF(A32="","",'By Teacher'!B19) | C32: =IF(A32="","",'By Teacher'!C19) | D32: =IF(A32="","",SUMIFS(Donations!$D:$D,Donations!$H:$H,A32,Donations!$F:$F,">="&'Daily Challenges'!$C$5,Donations!$F:$F,"<="&'Daily Challenges'!$D$5)) | E32: {=IF(A32="","",IF(N(F32)<=0,"—",INDEX(Students!$A$2:$A$601,MATCH(1,(Students!$B$2:$B$601=A32)*(Students!$I$2:$I$601=F32),0))&IF(COUNTIFS(Students!$B$2:$B$601,A32,Students!$I$2:$I$601,F32)>1," (tie)","")))} | F32: =IF(A32="","",_xlfn.MAXIFS(Students!$I$2:$I$601,Students!$B$2:$B$601,A32)) | G32: =IF(OR(A32="",N(C32)=0),"",COUNTIFS(Students!$B:$B,A32,Students!$F:$F,">="&MAX(0.01,N('Daily Challenges'!$G$7)))/C32) | H32: =IF(OR(A32="",N(C32)=0),"",COUNTIFS(Students!$B:$B,A32,Students!$H:$H,">0")/C32)
... A50: =IF('By Teacher'!A37="","",'By Teacher'!A37) | B50: =IF(A50="","",'By Teacher'!B37) | C50: =IF(A50="","",'By Teacher'!C37) | D50: =IF(A50="","",SUMIFS(Donations!$D:$D,Donations!$H:$H,A50,Donations!$F:$F,">="&'Daily Challenges'!$C$5,Donations!$F:$F,"<="&'Daily Challenges'!$D$5)) | E50: {=IF(A50="","",IF(N(F50)<=0,"—",INDEX(Students!$A$2:$A$601,MATCH(1,(Students!$B$2:$B$601=A50)*(Students!$I$2:$I$601=F50),0))&IF(COUNTIFS(Students!$B$2:$B$601,A50,Students!$I$2:$I$601,F50)>1," (tie)","")))} | F50: =IF(A50="","",_xlfn.MAXIFS(Students!$I$2:$I$601,Students!$B$2:$B$601,A50)) | G50: =IF(OR(A50="",N(C50)=0),"",COUNTIFS(Students!$B:$B,A50,Students!$F:$F,">="&MAX(0.01,N('Daily Challenges'!$G$7)))/C50) | H50: =IF(OR(A50="",N(C50)=0),"",COUNTIFS(Students!$B:$B,A50,Students!$H:$H,">0")/C50)
A52: GRADE SCORES
A53: Grade | C53: Grade vs. Grade $ | D53: Kickoff Weekend Challenge $ | E53: Kickoff Weekend Challenge: winning class
A54: P3 | C54: =SUMIFS(Donations!$D:$D,Donations!$I:$I,A54,Donations!$F:$F,">="&'Daily Challenges'!$C$11,Donations!$F:$F,"<="&'Daily Challenges'!$D$11) | D54: =_xlfn.MAXIFS($D$21:$D$50,$B$21:$B$50,A54) | E54: {=IF(N(D54)<=0,"—",INDEX($A$21:$A$50,MATCH(1,($B$21:$B$50&""=A54)*($D$21:$D$50=D54),0))&IF(COUNTIFS($B$21:$B$50,A54,$D$21:$D$50,D54)>1," (tie)",""))}
A55: P4 | C55: =SUMIFS(Donations!$D:$D,Donations!$I:$I,A55,Donations!$F:$F,">="&'Daily Challenges'!$C$11,Donations!$F:$F,"<="&'Daily Challenges'!$D$11) | D55: =_xlfn.MAXIFS($D$21:$D$50,$B$21:$B$50,A55) | E55: {=IF(N(D55)<=0,"—",INDEX($A$21:$A$50,MATCH(1,($B$21:$B$50&""=A55)*($D$21:$D$50=D55),0))&IF(COUNTIFS($B$21:$B$50,A55,$D$21:$D$50,D55)>1," (tie)",""))}
A56: K | C56: =SUMIFS(Donations!$D:$D,Donations!$I:$I,A56,Donations!$F:$F,">="&'Daily Challenges'!$C$11,Donations!$F:$F,"<="&'Daily Challenges'!$D$11) | D56: =_xlfn.MAXIFS($D$21:$D$50,$B$21:$B$50,A56) | E56: {=IF(N(D56)<=0,"—",INDEX($A$21:$A$50,MATCH(1,($B$21:$B$50&""=A56)*($D$21:$D$50=D56),0))&IF(COUNTIFS($B$21:$B$50,A56,$D$21:$D$50,D56)>1," (tie)",""))}
A57: 1 | C57: =SUMIFS(Donations!$D:$D,Donations!$I:$I,A57,Donations!$F:$F,">="&'Daily Challenges'!$C$11,Donations!$F:$F,"<="&'Daily Challenges'!$D$11) | D57: =_xlfn.MAXIFS($D$21:$D$50,$B$21:$B$50,A57) | E57: {=IF(N(D57)<=0,"—",INDEX($A$21:$A$50,MATCH(1,($B$21:$B$50&""=A57)*($D$21:$D$50=D57),0))&IF(COUNTIFS($B$21:$B$50,A57,$D$21:$D$50,D57)>1," (tie)",""))}
A58: 2 | C58: =SUMIFS(Donations!$D:$D,Donations!$I:$I,A58,Donations!$F:$F,">="&'Daily Challenges'!$C$11,Donations!$F:$F,"<="&'Daily Challenges'!$D$11) | D58: =_xlfn.MAXIFS($D$21:$D$50,$B$21:$B$50,A58) | E58: {=IF(N(D58)<=0,"—",INDEX($A$21:$A$50,MATCH(1,($B$21:$B$50&""=A58)*($D$21:$D$50=D58),0))&IF(COUNTIFS($B$21:$B$50,A58,$D$21:$D$50,D58)>1," (tie)",""))}
A59: 3 | C59: =SUMIFS(Donations!$D:$D,Donations!$I:$I,A59,Donations!$F:$F,">="&'Daily Challenges'!$C$11,Donations!$F:$F,"<="&'Daily Challenges'!$D$11) | D59: =_xlfn.MAXIFS($D$21:$D$50,$B$21:$B$50,A59) | E59: {=IF(N(D59)<=0,"—",INDEX($A$21:$A$50,MATCH(1,($B$21:$B$50&""=A59)*($D$21:$D$50=D59),0))&IF(COUNTIFS($B$21:$B$50,A59,$D$21:$D$50,D59)>1," (tie)",""))}
A60: 4 | C60: =SUMIFS(Donations!$D:$D,Donations!$I:$I,A60,Donations!$F:$F,">="&'Daily Challenges'!$C$11,Donations!$F:$F,"<="&'Daily Challenges'!$D$11) | D60: =_xlfn.MAXIFS($D$21:$D$50,$B$21:$B$50,A60) | E60: {=IF(N(D60)<=0,"—",INDEX($A$21:$A$50,MATCH(1,($B$21:$B$50&""=A60)*($D$21:$D$50=D60),0))&IF(COUNTIFS($B$21:$B$50,A60,$D$21:$D$50,D60)>1," (tie)",""))}
A61: 5 | C61: =SUMIFS(Donations!$D:$D,Donations!$I:$I,A61,Donations!$F:$F,">="&'Daily Challenges'!$C$11,Donations!$F:$F,"<="&'Daily Challenges'!$D$11) | D61: =_xlfn.MAXIFS($D$21:$D$50,$B$21:$B$50,A61) | E61: {=IF(N(D61)<=0,"—",INDEX($A$21:$A$50,MATCH(1,($B$21:$B$50&""=A61)*($D$21:$D$50=D61),0))&IF(COUNTIFS($B$21:$B$50,A61,$D$21:$D$50,D61)>1," (tie)",""))}
...

Sheet Donations
A1: Date | B1: Student (as on OneCause) | C1: Donor | D1: Amount | E1: Method | F1: Day (auto) | G1: Student on list (auto) | H1: Teacher (auto) | I1: Grade (auto)
A2: 46339.458 | B2: Daniel Martinez | C2: Ella Martinez | D2: 25 | E2: OneCause | F2: =IF(A2="","",IFERROR(INT(A2),"check date")) | G2: =IF(B2="","",IFERROR(INDEX(Students!$A:$A,MATCH(TRIM(B2),Students!$A:$A,0)),"NOT ON LIST")) | H2: =IF(OR(G2="",G2="NOT ON LIST"),"",VLOOKUP(G2,Students!$A:$C,2,FALSE)) | I2: =IF(OR(G2="",G2="NOT ON LIST"),"",VLOOKUP(G2,Students!$A:$C,3,FALSE)&"")
A3: 46334.594 | B3: Clara Flores | C3: Santiago Flores | D3: 25 | E3: OneCause | F3: =IF(A3="","",IFERROR(INT(A3),"check date")) | G3: =IF(B3="","",IFERROR(INDEX(Students!$A:$A,MATCH(TRIM(B3),Students!$A:$A,0)),"NOT ON LIST")) | H3: =IF(OR(G3="",G3="NOT ON LIST"),"",VLOOKUP(G3,Students!$A:$C,2,FALSE)) | I3: =IF(OR(G3="",G3="NOT ON LIST"),"",VLOOKUP(G3,Students!$A:$C,3,FALSE)&"")
A4: 46325.76 | B4: Adrian Nguyen | C4: Gabriel Nguyen | D4: 150 | E4: OneCause | F4: =IF(A4="","",IFERROR(INT(A4),"check date")) | G4: =IF(B4="","",IFERROR(INDEX(Students!$A:$A,MATCH(TRIM(B4),Students!$A:$A,0)),"NOT ON LIST")) | H4: =IF(OR(G4="",G4="NOT ON LIST"),"",VLOOKUP(G4,Students!$A:$C,2,FALSE)) | I4: =IF(OR(G4="",G4="NOT ON LIST"),"",VLOOKUP(G4,Students!$A:$C,3,FALSE)&"")
A5: 46326.771 | B5: Harper Morales | C5: Liam Morales | D5: 25 | E5: OneCause | F5: =IF(A5="","",IFERROR(INT(A5),"check date")) | G5: =IF(B5="","",IFERROR(INDEX(Students!$A:$A,MATCH(TRIM(B5),Students!$A:$A,0)),"NOT ON LIST")) | H5: =IF(OR(G5="",G5="NOT ON LIST"),"",VLOOKUP(G5,Students!$A:$C,2,FALSE)) | I5: =IF(OR(G5="",G5="NOT ON LIST"),"",VLOOKUP(G5,Students!$A:$C,3,FALSE)&"")
A6: 46327.729 | B6: Maya Patel | C6: Joseph Patel | D6: 150 | E6: OneCause | F6: =IF(A6="","",IFERROR(INT(A6),"check date")) | G6: =IF(B6="","",IFERROR(INDEX(Students!$A:$A,MATCH(TRIM(B6),Students!$A:$A,0)),"NOT ON LIST")) | H6: =IF(OR(G6="",G6="NOT ON LIST"),"",VLOOKUP(G6,Students!$A:$C,2,FALSE)) | I6: =IF(OR(G6="",G6="NOT ON LIST"),"",VLOOKUP(G6,Students!$A:$C,3,FALSE)&"")
A7: 46326.479 | B7: Santiago Alvarez | C7: Samuel Alvarez | D7: 100 | E7: OneCause | F7: =IF(A7="","",IFERROR(INT(A7),"check date")) | G7: =IF(B7="","",IFERROR(INDEX(Students!$A:$A,MATCH(TRIM(B7),Students!$A:$A,0)),"NOT ON LIST")) | H7: =IF(OR(G7="",G7="NOT ON LIST"),"",VLOOKUP(G7,Students!$A:$C,2,FALSE)) | I7: =IF(OR(G7="",G7="NOT ON LIST"),"",VLOOKUP(G7,Students!$A:$C,3,FALSE)&"")
A8: 46335.385 | B8: Amelia Vasquez | C8: Emma Vasquez | D8: 50 | E8: OneCause | F8: =IF(A8="","",IFERROR(INT(A8),"check date")) | G8: =IF(B8="","",IFERROR(INDEX(Students!$A:$A,MATCH(TRIM(B8),Students!$A:$A,0)),"NOT ON LIST")) | H8: =IF(OR(G8="",G8="NOT ON LIST"),"",VLOOKUP(G8,Students!$A:$C,2,FALSE)) | I8: =IF(OR(G8="",G8="NOT ON LIST"),"",VLOOKUP(G8,Students!$A:$C,3,FALSE)&"")
A9: 46331.802 | B9: Joseph Sanchez | C9: Diego Sanchez | D9: 50 | E9: OneCause | F9: =IF(A9="","",IFERROR(INT(A9),"check date")) | G9: =IF(B9="","",IFERROR(INDEX(Students!$A:$A,MATCH(TRIM(B9),Students!$A:$A,0)),"NOT ON LIST")) | H9: =IF(OR(G9="",G9="NOT ON LIST"),"",VLOOKUP(G9,Students!$A:$C,2,FALSE)) | I9: =IF(OR(G9="",G9="NOT ON LIST"),"",VLOOKUP(G9,Students!$A:$C,3,FALSE)&"")
A10: 46332 | B10: Nicolas Cruz | C10: Joseph Cruz | D10: 50 | E10: Check | F10: =IF(A10="","",IFERROR(INT(A10),"check date")) | G10: =IF(B10="","",IFERROR(INDEX(Students!$A:$A,MATCH(TRIM(B10),Students!$A:$A,0)),"NOT ON LIST")) | H10: =IF(OR(G10="",G10="NOT ON LIST"),"",VLOOKUP(G10,Students!$A:$C,2,FALSE)) | I10: =IF(OR(G10="",G10="NOT ON LIST"),"",VLOOKUP(G10,Students!$A:$C,3,FALSE)&"")
A11: 46329.573 | B11: Mateo Sullivan | C11: Diego Sullivan | D11: 50 | E11: OneCause | F11: =IF(A11="","",IFERROR(INT(A11),"check date")) | G11: =IF(B11="","",IFERROR(INDEX(Students!$A:$A,MATCH(TRIM(B11),Students!$A:$A,0)),"NOT ON LIST")) | H11: =IF(OR(G11="",G11="NOT ON LIST"),"",VLOOKUP(G11,Students!$A:$C,2,FALSE)) | I11: =IF(OR(G11="",G11="NOT ON LIST"),"",VLOOKUP(G11,Students!$A:$C,3,FALSE)&"")
A12: 46335.531 | B12: Chloe Ortiz | C12: Isaac Ortiz | D12: 150 | E12: OneCause | F12: =IF(A12="","",IFERROR(INT(A12),"check date")) | G12: =IF(B12="","",IFERROR(INDEX(Students!$A:$A,MATCH(TRIM(B12),Students!$A:$A,0)),"NOT ON LIST")) | H12: =IF(OR(G12="",G12="NOT ON LIST"),"",VLOOKUP(G12,Students!$A:$C,2,FALSE)) | I12: =IF(OR(G12="",G12="NOT ON LIST"),"",VLOOKUP(G12,Students!$A:$C,3,FALSE)&"")
A13: 46339.865 | B13: Elijah Cruz | C13: Camila Cruz | D13: 150 | E13: OneCause | F13: =IF(A13="","",IFERROR(INT(A13),"check date")) | G13: =IF(B13="","",IFERROR(INDEX(Students!$A:$A,MATCH(TRIM(B13),Students!$A:$A,0)),"NOT ON LIST")) | H13: =IF(OR(G13="",G13="NOT ON LIST"),"",VLOOKUP(G13,Students!$A:$C,2,FALSE)) | I13: =IF(OR(G13="",G13="NOT ON LIST"),"",VLOOKUP(G13,Students!$A:$C,3,FALSE)&"")
... A1254: 46338.76 | B1254: Noah Mendoza | C1254: Amelia Mendoza | D1254: 25 | E1254: OneCause | F1254: =IF(A1254="","",IFERROR(INT(A1254),"check date")) | G1254: =IF(B1254="","",IFERROR(INDEX(Students!$A:$A,MATCH(TRIM(B1254),Students!$A:$A,0)),"NOT ON LIST")) | H1254: =IF(OR(G1254="",G1254="NOT ON LIST"),"",VLOOKUP(G1254,Students!$A:$C,2,FALSE)) | I1254: =IF(OR(G1254="",G1254="NOT ON LIST"),"",VLOOKUP(G1254,Students!$A:$C,3,FALSE)&"")
F1255: =IF(A1255="","",IFERROR(INT(A1255),"check date")) | G1255: =IF(B1255="","",IFERROR(INDEX(Students!$A:$A,MATCH(TRIM(B1255),Students!$A:$A,0)),"NOT ON LIST")) | H1255: =IF(OR(G1255="",G1255="NOT ON LIST"),"",VLOOKUP(G1255,Students!$A:$C,2,FALSE)) | I1255: =IF(OR(G1255="",G1255="NOT ON LIST"),"",VLOOKUP(G1255,Students!$A:$C,3,FALSE)&"")
F1256: =IF(A1256="","",IFERROR(INT(A1256),"check date")) | G1256: =IF(B1256="","",IFERROR(INDEX(Students!$A:$A,MATCH(TRIM(B1256),Students!$A:$A,0)),"NOT ON LIST")) | H1256: =IF(OR(G1256="",G1256="NOT ON LIST"),"",VLOOKUP(G1256,Students!$A:$C,2,FALSE)) | I1256: =IF(OR(G1256="",G1256="NOT ON LIST"),"",VLOOKUP(G1256,Students!$A:$C,3,FALSE)&"")
F1257: =IF(A1257="","",IFERROR(INT(A1257),"check date")) | G1257: =IF(B1257="","",IFERROR(INDEX(Students!$A:$A,MATCH(TRIM(B1257),Students!$A:$A,0)),"NOT ON LIST")) | H1257: =IF(OR(G1257="",G1257="NOT ON LIST"),"",VLOOKUP(G1257,Students!$A:$C,2,FALSE)) | I1257: =IF(OR(G1257="",G1257="NOT ON LIST"),"",VLOOKUP(G1257,Students!$A:$C,3,FALSE)&"")
F1258: =IF(A1258="","",IFERROR(INT(A1258),"check date")) | G1258: =IF(B1258="","",IFERROR(INDEX(Students!$A:$A,MATCH(TRIM(B1258),Students!$A:$A,0)),"NOT ON LIST")) | H1258: =IF(OR(G1258="",G1258="NOT ON LIST"),"",VLOOKUP(G1258,Students!$A:$C,2,FALSE)) | I1258: =IF(OR(G1258="",G1258="NOT ON LIST"),"",VLOOKUP(G1258,Students!$A:$C,3,FALSE)&"")
F1259: =IF(A1259="","",IFERROR(INT(A1259),"check date")) | G1259: =IF(B1259="","",IFERROR(INDEX(Students!$A:$A,MATCH(TRIM(B1259),Students!$A:$A,0)),"NOT ON LIST")) | H1259: =IF(OR(G1259="",G1259="NOT ON LIST"),"",VLOOKUP(G1259,Students!$A:$C,2,FALSE)) | I1259: =IF(OR(G1259="",G1259="NOT ON LIST"),"",VLOOKUP(G1259,Students!$A:$C,3,FALSE)&"")
F1260: =IF(A1260="","",IFERROR(INT(A1260),"check date")) | G1260: =IF(B1260="","",IFERROR(INDEX(Students!$A:$A,MATCH(TRIM(B1260),Students!$A:$A,0)),"NOT ON LIST")) | H1260: =IF(OR(G1260="",G1260="NOT ON LIST"),"",VLOOKUP(G1260,Students!$A:$C,2,FALSE)) | I1260: =IF(OR(G1260="",G1260="NOT ON LIST"),"",VLOOKUP(G1260,Students!$A:$C,3,FALSE)&"")
F1261: =IF(A1261="","",IFERROR(INT(A1261),"check date")) | G1261: =IF(B1261="","",IFERROR(INDEX(Students!$A:$A,MATCH(TRIM(B1261),Students!$A:$A,0)),"NOT ON LIST")) | H1261: =IF(OR(G1261="",G1261="NOT ON LIST"),"",VLOOKUP(G1261,Students!$A:$C,2,FALSE)) | I1261: =IF(OR(G1261="",G1261="NOT ON LIST"),"",VLOOKUP(G1261,Students!$A:$C,3,FALSE)&"")
F1262: =IF(A1262="","",IFERROR(INT(A1262),"check date")) | G1262: =IF(B1262="","",IFERROR(INDEX(Students!$A:$A,MATCH(TRIM(B1262),Students!$A:$A,0)),"NOT ON LIST")) | H1262: =IF(OR(G1262="",G1262="NOT ON LIST"),"",VLOOKUP(G1262,Students!$A:$C,2,FALSE)) | I1262: =IF(OR(G1262="",G1262="NOT ON LIST"),"",VLOOKUP(G1262,Students!$A:$C,3,FALSE)&"")
F1263: =IF(A1263="","",IFERROR(INT(A1263),"check date")) | G1263: =IF(B1263="","",IFERROR(INDEX(Students!$A:$A,MATCH(TRIM(B1263),Students!$A:$A,0)),"NOT ON LIST")) | H1263: =IF(OR(G1263="",G1263="NOT ON LIST"),"",VLOOKUP(G1263,Students!$A:$C,2,FALSE)) | I1263: =IF(OR(G1263="",G1263="NOT ON LIST"),"",VLOOKUP(G1263,Students!$A:$C,3,FALSE)&"")
F1264: =IF(A1264="","",IFERROR(INT(A1264),"check date")) | G1264: =IF(B1264="","",IFERROR(INDEX(Students!$A:$A,MATCH(TRIM(B1264),Students!$A:$A,0)),"NOT ON LIST")) | H1264: =IF(OR(G1264="",G1264="NOT ON LIST"),"",VLOOKUP(G1264,Students!$A:$C,2,FALSE)) | I1264: =IF(OR(G1264="",G1264="NOT ON LIST"),"",VLOOKUP(G1264,Students!$A:$C,3,FALSE)&"")
F1265: =IF(A1265="","",IFERROR(INT(A1265),"check date")) | G1265: =IF(B1265="","",IFERROR(INDEX(Students!$A:$A,MATCH(TRIM(B1265),Students!$A:$A,0)),"NOT ON LIST")) | H1265: =IF(OR(G1265="",G1265="NOT ON LIST"),"",VLOOKUP(G1265,Students!$A:$C,2,FALSE)) | I1265: =IF(OR(G1265="",G1265="NOT ON LIST"),"",VLOOKUP(G1265,Students!$A:$C,3,FALSE)&"")
F1266: =IF(A1266="","",IFERROR(INT(A1266),"check date")) | G1266: =IF(B1266="","",IFERROR(INDEX(Students!$A:$A,MATCH(TRIM(B1266),Students!$A:$A,0)),"NOT ON LIST")) | H1266: =IF(OR(G1266="",G1266="NOT ON LIST"),"",VLOOKUP(G1266,Students!$A:$C,2,FALSE)) | I1266: =IF(OR(G1266="",G1266="NOT ON LIST"),"",VLOOKUP(G1266,Students!$A:$C,3,FALSE)&"")
... F3001: =IF(A3001="","",IFERROR(INT(A3001),"check date")) | G3001: =IF(B3001="","",IFERROR(INDEX(Students!$A:$A,MATCH(TRIM(B3001),Students!$A:$A,0)),"NOT ON LIST")) | H3001: =IF(OR(G3001="",G3001="NOT ON LIST"),"",VLOOKUP(G3001,Students!$A:$C,2,FALSE)) | I3001: =IF(OR(G3001="",G3001="NOT ON LIST"),"",VLOOKUP(G3001,Students!$A:$C,3,FALSE)&"")

Sheet Students
A1: Student | B1: Teacher | C1: Grade | D1: Total $ (auto) | E1: Donated? (auto) | F1: ="$ "&TEXT('Daily Challenges'!$C$7,"m/d")&IF('Daily Challenges'!$D$7>'Daily Challenges'!$C$7,"–"&TEXT('Daily Challenges'!$D$7,"m/d"),"") | G1: ="$ "&TEXT('Daily Challenges'!$C$8,"m/d")&IF('Daily Challenges'!$D$8>'Daily Challenges'!$C$8,"–"&TEXT('Daily Challenges'!$D$8,"m/d"),"") | H1: ="$ thru "&TEXT('Daily Challenges'!$D$9,"m/d") | I1: ="$ "&TEXT('Daily Challenges'!$C$10,"m/d")&IF('Daily Challenges'!$D$10>'Daily Challenges'!$C$10,"–"&TEXT('Daily Challenges'!$D$10,"m/d"),"") | J1: ="$ thru "&TEXT('Daily Challenges'!$D$12,"m/d")
A2: Diego Morales | B2: Ms. Alvarez | C2: P3 | D2: =IF(A2="","",SUMIFS(Donations!$D:$D,Donations!$G:$G,A2)) | E2: =IF(A2="","",IF(D2>0,"Yes","")) | F2: =IF($A2="","",SUMIFS(Donations!$D:$D,Donations!$G:$G,$A2,Donations!$F:$F,">="&'Daily Challenges'!$C$7,Donations!$F:$F,"<="&'Daily Challenges'!$D$7)) | G2: =IF($A2="","",SUMIFS(Donations!$D:$D,Donations!$G:$G,$A2,Donations!$F:$F,">="&'Daily Challenges'!$C$8,Donations!$F:$F,"<="&'Daily Challenges'!$D$8)) | H2: =IF($A2="","",SUMIFS(Donations!$D:$D,Donations!$G:$G,$A2,Donations!$F:$F,"<="&'Daily Challenges'!$D$9)) | I2: =IF($A2="","",SUMIFS(Donations!$D:$D,Donations!$G:$G,$A2,Donations!$F:$F,">="&'Daily Challenges'!$C$10,Donations!$F:$F,"<="&'Daily Challenges'!$D$10)) | J2: =IF($A2="","",SUMIFS(Donations!$D:$D,Donations!$G:$G,$A2,Donations!$F:$F,"<="&'Daily Challenges'!$D$12))
A3: Nora Patel | B3: Ms. Alvarez | C3: P3 | D3: =IF(A3="","",SUMIFS(Donations!$D:$D,Donations!$G:$G,A3)) | E3: =IF(A3="","",IF(D3>0,"Yes","")) | F3: =IF($A3="","",SUMIFS(Donations!$D:$D,Donations!$G:$G,$A3,Donations!$F:$F,">="&'Daily Challenges'!$C$7,Donations!$F:$F,"<="&'Daily Challenges'!$D$7)) | G3: =IF($A3="","",SUMIFS(Donations!$D:$D,Donations!$G:$G,$A3,Donations!$F:$F,">="&'Daily Challenges'!$C$8,Donations!$F:$F,"<="&'Daily Challenges'!$D$8)) | H3: =IF($A3="","",SUMIFS(Donations!$D:$D,Donations!$G:$G,$A3,Donations!$F:$F,"<="&'Daily Challenges'!$D$9)) | I3: =IF($A3="","",SUMIFS(Donations!$D:$D,Donations!$G:$G,$A3,Donations!$F:$F,">="&'Daily Challenges'!$C$10,Donations!$F:$F,"<="&'Daily Challenges'!$D$10)) | J3: =IF($A3="","",SUMIFS(Donations!$D:$D,Donations!$G:$G,$A3,Donations!$F:$F,"<="&'Daily Challenges'!$D$12))
A4: Thomas Williams | B4: Ms. Alvarez | C4: P3 | D4: =IF(A4="","",SUMIFS(Donations!$D:$D,Donations!$G:$G,A4)) | E4: =IF(A4="","",IF(D4>0,"Yes","")) | F4: =IF($A4="","",SUMIFS(Donations!$D:$D,Donations!$G:$G,$A4,Donations!$F:$F,">="&'Daily Challenges'!$C$7,Donations!$F:$F,"<="&'Daily Challenges'!$D$7)) | G4: =IF($A4="","",SUMIFS(Donations!$D:$D,Donations!$G:$G,$A4,Donations!$F:$F,">="&'Daily Challenges'!$C$8,Donations!$F:$F,"<="&'Daily Challenges'!$D$8)) | H4: =IF($A4="","",SUMIFS(Donations!$D:$D,Donations!$G:$G,$A4,Donations!$F:$F,"<="&'Daily Challenges'!$D$9)) | I4: =IF($A4="","",SUMIFS(Donations!$D:$D,Donations!$G:$G,$A4,Donations!$F:$F,">="&'Daily Challenges'!$C$10,Donations!$F:$F,"<="&'Daily Challenges'!$D$10)) | J4: =IF($A4="","",SUMIFS(Donations!$D:$D,Donations!$G:$G,$A4,Donations!$F:$F,"<="&'Daily Challenges'!$D$12))
A5: Mia Byrne | B5: Ms. Alvarez | C5: P3 | D5: =IF(A5="","",SUMIFS(Donations!$D:$D,Donations!$G:$G,A5)) | E5: =IF(A5="","",IF(D5>0,"Yes","")) | F5: =IF($A5="","",SUMIFS(Donations!$D:$D,Donations!$G:$G,$A5,Donations!$F:$F,">="&'Daily Challenges'!$C$7,Donations!$F:$F,"<="&'Daily Challenges'!$D$7)) | G5: =IF($A5="","",SUMIFS(Donations!$D:$D,Donations!$G:$G,$A5,Donations!$F:$F,">="&'Daily Challenges'!$C$8,Donations!$F:$F,"<="&'Daily Challenges'!$D$8)) | H5: =IF($A5="","",SUMIFS(Donations!$D:$D,Donations!$G:$G,$A5,Donations!$F:$F,"<="&'Daily Challenges'!$D$9)) | I5: =IF($A5="","",SUMIFS(Donations!$D:$D,Donations!$G:$G,$A5,Donations!$F:$F,">="&'Daily Challenges'!$C$10,Donations!$F:$F,"<="&'Daily Challenges'!$D$10)) | J5: =IF($A5="","",SUMIFS(Donations!$D:$D,Donations!$G:$G,$A5,Donations!$F:$F,"<="&'Daily Challenges'!$D$12))
A6: Nicolas Sullivan | B6: Ms. Alvarez | C6: P3 | D6: =IF(A6="","",SUMIFS(Donations!$D:$D,Donations!$G:$G,A6)) | E6: =IF(A6="","",IF(D6>0,"Yes","")) | F6: =IF($A6="","",SUMIFS(Donations!$D:$D,Donations!$G:$G,$A6,Donations!$F:$F,">="&'Daily Challenges'!$C$7,Donations!$F:$F,"<="&'Daily Challenges'!$D$7)) | G6: =IF($A6="","",SUMIFS(Donations!$D:$D,Donations!$G:$G,$A6,Donations!$F:$F,">="&'Daily Challenges'!$C$8,Donations!$F:$F,"<="&'Daily Challenges'!$D$8)) | H6: =IF($A6="","",SUMIFS(Donations!$D:$D,Donations!$G:$G,$A6,Donations!$F:$F,"<="&'Daily Challenges'!$D$9)) | I6: =IF($A6="","",SUMIFS(Donations!$D:$D,Donations!$G:$G,$A6,Donations!$F:$F,">="&'Daily Challenges'!$C$10,Donations!$F:$F,"<="&'Daily Challenges'!$D$10)) | J6: =IF($A6="","",SUMIFS(Donations!$D:$D,Donations!$G:$G,$A6,Donations!$F:$F,"<="&'Daily Challenges'!$D$12))
A7: Grace Kelly | B7: Ms. Alvarez | C7: P3 | D7: =IF(A7="","",SUMIFS(Donations!$D:$D,Donations!$G:$G,A7)) | E7: =IF(A7="","",IF(D7>0,"Yes","")) | F7: =IF($A7="","",SUMIFS(Donations!$D:$D,Donations!$G:$G,$A7,Donations!$F:$F,">="&'Daily Challenges'!$C$7,Donations!$F:$F,"<="&'Daily Challenges'!$D$7)) | G7: =IF($A7="","",SUMIFS(Donations!$D:$D,Donations!$G:$G,$A7,Donations!$F:$F,">="&'Daily Challenges'!$C$8,Donations!$F:$F,"<="&'Daily Challenges'!$D$8)) | H7: =IF($A7="","",SUMIFS(Donations!$D:$D,Donations!$G:$G,$A7,Donations!$F:$F,"<="&'Daily Challenges'!$D$9)) | I7: =IF($A7="","",SUMIFS(Donations!$D:$D,Donations!$G:$G,$A7,Donations!$F:$F,">="&'Daily Challenges'!$C$10,Donations!$F:$F,"<="&'Daily Challenges'!$D$10)) | J7: =IF($A7="","",SUMIFS(Donations!$D:$D,Donations!$G:$G,$A7,Donations!$F:$F,"<="&'Daily Challenges'!$D$12))
A8: Adrian Nguyen | B8: Ms. Alvarez | C8: P3 | D8: =IF(A8="","",SUMIFS(Donations!$D:$D,Donations!$G:$G,A8)) | E8: =IF(A8="","",IF(D8>0,"Yes","")) | F8: =IF($A8="","",SUMIFS(Donations!$D:$D,Donations!$G:$G,$A8,Donations!$F:$F,">="&'Daily Challenges'!$C$7,Donations!$F:$F,"<="&'Daily Challenges'!$D$7)) | G8: =IF($A8="","",SUMIFS(Donations!$D:$D,Donations!$G:$G,$A8,Donations!$F:$F,">="&'Daily Challenges'!$C$8,Donations!$F:$F,"<="&'Daily Challenges'!$D$8)) | H8: =IF($A8="","",SUMIFS(Donations!$D:$D,Donations!$G:$G,$A8,Donations!$F:$F,"<="&'Daily Challenges'!$D$9)) | I8: =IF($A8="","",SUMIFS(Donations!$D:$D,Donations!$G:$G,$A8,Donations!$F:$F,">="&'Daily Challenges'!$C$10,Donations!$F:$F,"<="&'Daily Challenges'!$D$10)) | J8: =IF($A8="","",SUMIFS(Donations!$D:$D,Donations!$G:$G,$A8,Donations!$F:$F,"<="&'Daily Challenges'!$D$12))
A9: Julian Castillo | B9: Ms. Alvarez | C9: P3 | D9: =IF(A9="","",SUMIFS(Donations!$D:$D,Donations!$G:$G,A9)) | E9: =IF(A9="","",IF(D9>0,"Yes","")) | F9: =IF($A9="","",SUMIFS(Donations!$D:$D,Donations!$G:$G,$A9,Donations!$F:$F,">="&'Daily Challenges'!$C$7,Donations!$F:$F,"<="&'Daily Challenges'!$D$7)) | G9: =IF($A9="","",SUMIFS(Donations!$D:$D,Donations!$G:$G,$A9,Donations!$F:$F,">="&'Daily Challenges'!$C$8,Donations!$F:$F,"<="&'Daily Challenges'!$D$8)) | H9: =IF($A9="","",SUMIFS(Donations!$D:$D,Donations!$G:$G,$A9,Donations!$F:$F,"<="&'Daily Challenges'!$D$9)) | I9: =IF($A9="","",SUMIFS(Donations!$D:$D,Donations!$G:$G,$A9,Donations!$F:$F,">="&'Daily Challenges'!$C$10,Donations!$F:$F,"<="&'Daily Challenges'!$D$10)) | J9: =IF($A9="","",SUMIFS(Donations!$D:$D,Donations!$G:$G,$A9,Donations!$F:$F,"<="&'Daily Challenges'!$D$12))
A10: James Garcia | B10: Ms. Alvarez | C10: P3 | D10: =IF(A10="","",SUMIFS(Donations!$D:$D,Donations!$G:$G,A10)) | E10: =IF(A10="","",IF(D10>0,"Yes","")) | F10: =IF($A10="","",SUMIFS(Donations!$D:$D,Donations!$G:$G,$A10,Donations!$F:$F,">="&'Daily Challenges'!$C$7,Donations!$F:$F,"<="&'Daily Challenges'!$D$7)) | G10: =IF($A10="","",SUMIFS(Donations!$D:$D,Donations!$G:$G,$A10,Donations!$F:$F,">="&'Daily Challenges'!$C$8,Donations!$F:$F,"<="&'Daily Challenges'!$D$8)) | H10: =IF($A10="","",SUMIFS(Donations!$D:$D,Donations!$G:$G,$A10,Donations!$F:$F,"<="&'Daily Challenges'!$D$9)) | I10: =IF($A10="","",SUMIFS(Donations!$D:$D,Donations!$G:$G,$A10,Donations!$F:$F,">="&'Daily Challenges'!$C$10,Donations!$F:$F,"<="&'Daily Challenges'!$D$10)) | J10: =IF($A10="","",SUMIFS(Donations!$D:$D,Donations!$G:$G,$A10,Donations!$F:$F,"<="&'Daily Challenges'!$D$12))
A11: Nicolas Johnson | B11: Ms. Alvarez | C11: P3 | D11: =IF(A11="","",SUMIFS(Donations!$D:$D,Donations!$G:$G,A11)) | E11: =IF(A11="","",IF(D11>0,"Yes","")) | F11: =IF($A11="","",SUMIFS(Donations!$D:$D,Donations!$G:$G,$A11,Donations!$F:$F,">="&'Daily Challenges'!$C$7,Donations!$F:$F,"<="&'Daily Challenges'!$D$7)) | G11: =IF($A11="","",SUMIFS(Donations!$D:$D,Donations!$G:$G,$A11,Donations!$F:$F,">="&'Daily Challenges'!$C$8,Donations!$F:$F,"<="&'Daily Challenges'!$D$8)) | H11: =IF($A11="","",SUMIFS(Donations!$D:$D,Donations!$G:$G,$A11,Donations!$F:$F,"<="&'Daily Challenges'!$D$9)) | I11: =IF($A11="","",SUMIFS(Donations!$D:$D,Donations!$G:$G,$A11,Donations!$F:$F,">="&'Daily Challenges'!$C$10,Donations!$F:$F,"<="&'Daily Challenges'!$D$10)) | J11: =IF($A11="","",SUMIFS(Donations!$D:$D,Donations!$G:$G,$A11,Donations!$F:$F,"<="&'Daily Challenges'!$D$12))
A12: Diego Reyes | B12: Ms. Alvarez | C12: P3 | D12: =IF(A12="","",SUMIFS(Donations!$D:$D,Donations!$G:$G,A12)) | E12: =IF(A12="","",IF(D12>0,"Yes","")) | F12: =IF($A12="","",SUMIFS(Donations!$D:$D,Donations!$G:$G,$A12,Donations!$F:$F,">="&'Daily Challenges'!$C$7,Donations!$F:$F,"<="&'Daily Challenges'!$D$7)) | G12: =IF($A12="","",SUMIFS(Donations!$D:$D,Donations!$G:$G,$A12,Donations!$F:$F,">="&'Daily Challenges'!$C$8,Donations!$F:$F,"<="&'Daily Challenges'!$D$8)) | H12: =IF($A12="","",SUMIFS(Donations!$D:$D,Donations!$G:$G,$A12,Donations!$F:$F,"<="&'Daily Challenges'!$D$9)) | I12: =IF($A12="","",SUMIFS(Donations!$D:$D,Donations!$G:$G,$A12,Donations!$F:$F,">="&'Daily Challenges'!$C$10,Donations!$F:$F,"<="&'Daily Challenges'!$D$10)) | J12: =IF($A12="","",SUMIFS(Donations!$D:$D,Donations!$G:$G,$A12,Donations!$F:$F,"<="&'Daily Challenges'!$D$12))
A13: Valentina Castillo | B13: Ms. Alvarez | C13: P3 | D13: =IF(A13="","",SUMIFS(Donations!$D:$D,Donations!$G:$G,A13)) | E13: =IF(A13="","",IF(D13>0,"Yes","")) | F13: =IF($A13="","",SUMIFS(Donations!$D:$D,Donations!$G:$G,$A13,Donations!$F:$F,">="&'Daily Challenges'!$C$7,Donations!$F:$F,"<="&'Daily Challenges'!$D$7)) | G13: =IF($A13="","",SUMIFS(Donations!$D:$D,Donations!$G:$G,$A13,Donations!$F:$F,">="&'Daily Challenges'!$C$8,Donations!$F:$F,"<="&'Daily Challenges'!$D$8)) | H13: =IF($A13="","",SUMIFS(Donations!$D:$D,Donations!$G:$G,$A13,Donations!$F:$F,"<="&'Daily Challenges'!$D$9)) | I13: =IF($A13="","",SUMIFS(Donations!$D:$D,Donations!$G:$G,$A13,Donations!$F:$F,">="&'Daily Challenges'!$C$10,Donations!$F:$F,"<="&'Daily Challenges'!$D$10)) | J13: =IF($A13="","",SUMIFS(Donations!$D:$D,Donations!$G:$G,$A13,Donations!$F:$F,"<="&'Daily Challenges'!$D$12))
... A425: Mateo Nguyen | B425: Mrs. Valdez | C425: 8 | D425: =IF(A425="","",SUMIFS(Donations!$D:$D,Donations!$G:$G,A425)) | E425: =IF(A425="","",IF(D425>0,"Yes","")) | F425: =IF($A425="","",SUMIFS(Donations!$D:$D,Donations!$G:$G,$A425,Donations!$F:$F,">="&'Daily Challenges'!$C$7,Donations!$F:$F,"<="&'Daily Challenges'!$D$7)) | G425: =IF($A425="","",SUMIFS(Donations!$D:$D,Donations!$G:$G,$A425,Donations!$F:$F,">="&'Daily Challenges'!$C$8,Donations!$F:$F,"<="&'Daily Challenges'!$D$8)) | H425: =IF($A425="","",SUMIFS(Donations!$D:$D,Donations!$G:$G,$A425,Donations!$F:$F,"<="&'Daily Challenges'!$D$9)) | I425: =IF($A425="","",SUMIFS(Donations!$D:$D,Donations!$G:$G,$A425,Donations!$F:$F,">="&'Daily Challenges'!$C$10,Donations!$F:$F,"<="&'Daily Challenges'!$D$10)) | J425: =IF($A425="","",SUMIFS(Donations!$D:$D,Donations!$G:$G,$A425,Donations!$F:$F,"<="&'Daily Challenges'!$D$12))
D426: =IF(A426="","",SUMIFS(Donations!$D:$D,Donations!$G:$G,A426)) | E426: =IF(A426="","",IF(D426>0,"Yes","")) | F426: =IF($A426="","",SUMIFS(Donations!$D:$D,Donations!$G:$G,$A426,Donations!$F:$F,">="&'Daily Challenges'!$C$7,Donations!$F:$F,"<="&'Daily Challenges'!$D$7)) | G426: =IF($A426="","",SUMIFS(Donations!$D:$D,Donations!$G:$G,$A426,Donations!$F:$F,">="&'Daily Challenges'!$C$8,Donations!$F:$F,"<="&'Daily Challenges'!$D$8)) | H426: =IF($A426="","",SUMIFS(Donations!$D:$D,Donations!$G:$G,$A426,Donations!$F:$F,"<="&'Daily Challenges'!$D$9)) | I426: =IF($A426="","",SUMIFS(Donations!$D:$D,Donations!$G:$G,$A426,Donations!$F:$F,">="&'Daily Challenges'!$C$10,Donations!$F:$F,"<="&'Daily Challenges'!$D$10)) | J426: =IF($A426="","",SUMIFS(Donations!$D:$D,Donations!$G:$G,$A426,Donations!$F:$F,"<="&'Daily Challenges'!$D$12))
D427: =IF(A427="","",SUMIFS(Donations!$D:$D,Donations!$G:$G,A427)) | E427: =IF(A427="","",IF(D427>0,"Yes","")) | F427: =IF($A427="","",SUMIFS(Donations!$D:$D,Donations!$G:$G,$A427,Donations!$F:$F,">="&'Daily Challenges'!$C$7,Donations!$F:$F,"<="&'Daily Challenges'!$D$7)) | G427: =IF($A427="","",SUMIFS(Donations!$D:$D,Donations!$G:$G,$A427,Donations!$F:$F,">="&'Daily Challenges'!$C$8,Donations!$F:$F,"<="&'Daily Challenges'!$D$8)) | H427: =IF($A427="","",SUMIFS(Donations!$D:$D,Donations!$G:$G,$A427,Donations!$F:$F,"<="&'Daily Challenges'!$D$9)) | I427: =IF($A427="","",SUMIFS(Donations!$D:$D,Donations!$G:$G,$A427,Donations!$F:$F,">="&'Daily Challenges'!$C$10,Donations!$F:$F,"<="&'Daily Challenges'!$D$10)) | J427: =IF($A427="","",SUMIFS(Donations!$D:$D,Donations!$G:$G,$A427,Donations!$F:$F,"<="&'Daily Challenges'!$D$12))
D428: =IF(A428="","",SUMIFS(Donations!$D:$D,Donations!$G:$G,A428)) | E428: =IF(A428="","",IF(D428>0,"Yes","")) | F428: =IF($A428="","",SUMIFS(Donations!$D:$D,Donations!$G:$G,$A428,Donations!$F:$F,">="&'Daily Challenges'!$C$7,Donations!$F:$F,"<="&'Daily Challenges'!$D$7)) | G428: =IF($A428="","",SUMIFS(Donations!$D:$D,Donations!$G:$G,$A428,Donations!$F:$F,">="&'Daily Challenges'!$C$8,Donations!$F:$F,"<="&'Daily Challenges'!$D$8)) | H428: =IF($A428="","",SUMIFS(Donations!$D:$D,Donations!$G:$G,$A428,Donations!$F:$F,"<="&'Daily Challenges'!$D$9)) | I428: =IF($A428="","",SUMIFS(Donations!$D:$D,Donations!$G:$G,$A428,Donations!$F:$F,">="&'Daily Challenges'!$C$10,Donations!$F:$F,"<="&'Daily Challenges'!$D$10)) | J428: =IF($A428="","",SUMIFS(Donations!$D:$D,Donations!$G:$G,$A428,Donations!$F:$F,"<="&'Daily Challenges'!$D$12))
D429: =IF(A429="","",SUMIFS(Donations!$D:$D,Donations!$G:$G,A429)) | E429: =IF(A429="","",IF(D429>0,"Yes","")) | F429: =IF($A429="","",SUMIFS(Donations!$D:$D,Donations!$G:$G,$A429,Donations!$F:$F,">="&'Daily Challenges'!$C$7,Donations!$F:$F,"<="&'Daily Challenges'!$D$7)) | G429: =IF($A429="","",SUMIFS(Donations!$D:$D,Donations!$G:$G,$A429,Donations!$F:$F,">="&'Daily Challenges'!$C$8,Donations!$F:$F,"<="&'Daily Challenges'!$D$8)) | H429: =IF($A429="","",SUMIFS(Donations!$D:$D,Donations!$G:$G,$A429,Donations!$F:$F,"<="&'Daily Challenges'!$D$9)) | I429: =IF($A429="","",SUMIFS(Donations!$D:$D,Donations!$G:$G,$A429,Donations!$F:$F,">="&'Daily Challenges'!$C$10,Donations!$F:$F,"<="&'Daily Challenges'!$D$10)) | J429: =IF($A429="","",SUMIFS(Donations!$D:$D,Donations!$G:$G,$A429,Donations!$F:$F,"<="&'Daily Challenges'!$D$12))
D430: =IF(A430="","",SUMIFS(Donations!$D:$D,Donations!$G:$G,A430)) | E430: =IF(A430="","",IF(D430>0,"Yes","")) | F430: =IF($A430="","",SUMIFS(Donations!$D:$D,Donations!$G:$G,$A430,Donations!$F:$F,">="&'Daily Challenges'!$C$7,Donations!$F:$F,"<="&'Daily Challenges'!$D$7)) | G430: =IF($A430="","",SUMIFS(Donations!$D:$D,Donations!$G:$G,$A430,Donations!$F:$F,">="&'Daily Challenges'!$C$8,Donations!$F:$F,"<="&'Daily Challenges'!$D$8)) | H430: =IF($A430="","",SUMIFS(Donations!$D:$D,Donations!$G:$G,$A430,Donations!$F:$F,"<="&'Daily Challenges'!$D$9)) | I430: =IF($A430="","",SUMIFS(Donations!$D:$D,Donations!$G:$G,$A430,Donations!$F:$F,">="&'Daily Challenges'!$C$10,Donations!$F:$F,"<="&'Daily Challenges'!$D$10)) | J430: =IF($A430="","",SUMIFS(Donations!$D:$D,Donations!$G:$G,$A430,Donations!$F:$F,"<="&'Daily Challenges'!$D$12))
D431: =IF(A431="","",SUMIFS(Donations!$D:$D,Donations!$G:$G,A431)) | E431: =IF(A431="","",IF(D431>0,"Yes","")) | F431: =IF($A431="","",SUMIFS(Donations!$D:$D,Donations!$G:$G,$A431,Donations!$F:$F,">="&'Daily Challenges'!$C$7,Donations!$F:$F,"<="&'Daily Challenges'!$D$7)) | G431: =IF($A431="","",SUMIFS(Donations!$D:$D,Donations!$G:$G,$A431,Donations!$F:$F,">="&'Daily Challenges'!$C$8,Donations!$F:$F,"<="&'Daily Challenges'!$D$8)) | H431: =IF($A431="","",SUMIFS(Donations!$D:$D,Donations!$G:$G,$A431,Donations!$F:$F,"<="&'Daily Challenges'!$D$9)) | I431: =IF($A431="","",SUMIFS(Donations!$D:$D,Donations!$G:$G,$A431,Donations!$F:$F,">="&'Daily Challenges'!$C$10,Donations!$F:$F,"<="&'Daily Challenges'!$D$10)) | J431: =IF($A431="","",SUMIFS(Donations!$D:$D,Donations!$G:$G,$A431,Donations!$F:$F,"<="&'Daily Challenges'!$D$12))
D432: =IF(A432="","",SUMIFS(Donations!$D:$D,Donations!$G:$G,A432)) | E432: =IF(A432="","",IF(D432>0,"Yes","")) | F432: =IF($A432="","",SUMIFS(Donations!$D:$D,Donations!$G:$G,$A432,Donations!$F:$F,">="&'Daily Challenges'!$C$7,Donations!$F:$F,"<="&'Daily Challenges'!$D$7)) | G432: =IF($A432="","",SUMIFS(Donations!$D:$D,Donations!$G:$G,$A432,Donations!$F:$F,">="&'Daily Challenges'!$C$8,Donations!$F:$F,"<="&'Daily Challenges'!$D$8)) | H432: =IF($A432="","",SUMIFS(Donations!$D:$D,Donations!$G:$G,$A432,Donations!$F:$F,"<="&'Daily Challenges'!$D$9)) | I432: =IF($A432="","",SUMIFS(Donations!$D:$D,Donations!$G:$G,$A432,Donations!$F:$F,">="&'Daily Challenges'!$C$10,Donations!$F:$F,"<="&'Daily Challenges'!$D$10)) | J432: =IF($A432="","",SUMIFS(Donations!$D:$D,Donations!$G:$G,$A432,Donations!$F:$F,"<="&'Daily Challenges'!$D$12))
D433: =IF(A433="","",SUMIFS(Donations!$D:$D,Donations!$G:$G,A433)) | E433: =IF(A433="","",IF(D433>0,"Yes","")) | F433: =IF($A433="","",SUMIFS(Donations!$D:$D,Donations!$G:$G,$A433,Donations!$F:$F,">="&'Daily Challenges'!$C$7,Donations!$F:$F,"<="&'Daily Challenges'!$D$7)) | G433: =IF($A433="","",SUMIFS(Donations!$D:$D,Donations!$G:$G,$A433,Donations!$F:$F,">="&'Daily Challenges'!$C$8,Donations!$F:$F,"<="&'Daily Challenges'!$D$8)) | H433: =IF($A433="","",SUMIFS(Donations!$D:$D,Donations!$G:$G,$A433,Donations!$F:$F,"<="&'Daily Challenges'!$D$9)) | I433: =IF($A433="","",SUMIFS(Donations!$D:$D,Donations!$G:$G,$A433,Donations!$F:$F,">="&'Daily Challenges'!$C$10,Donations!$F:$F,"<="&'Daily Challenges'!$D$10)) | J433: =IF($A433="","",SUMIFS(Donations!$D:$D,Donations!$G:$G,$A433,Donations!$F:$F,"<="&'Daily Challenges'!$D$12))
D434: =IF(A434="","",SUMIFS(Donations!$D:$D,Donations!$G:$G,A434)) | E434: =IF(A434="","",IF(D434>0,"Yes","")) | F434: =IF($A434="","",SUMIFS(Donations!$D:$D,Donations!$G:$G,$A434,Donations!$F:$F,">="&'Daily Challenges'!$C$7,Donations!$F:$F,"<="&'Daily Challenges'!$D$7)) | G434: =IF($A434="","",SUMIFS(Donations!$D:$D,Donations!$G:$G,$A434,Donations!$F:$F,">="&'Daily Challenges'!$C$8,Donations!$F:$F,"<="&'Daily Challenges'!$D$8)) | H434: =IF($A434="","",SUMIFS(Donations!$D:$D,Donations!$G:$G,$A434,Donations!$F:$F,"<="&'Daily Challenges'!$D$9)) | I434: =IF($A434="","",SUMIFS(Donations!$D:$D,Donations!$G:$G,$A434,Donations!$F:$F,">="&'Daily Challenges'!$C$10,Donations!$F:$F,"<="&'Daily Challenges'!$D$10)) | J434: =IF($A434="","",SUMIFS(Donations!$D:$D,Donations!$G:$G,$A434,Donations!$F:$F,"<="&'Daily Challenges'!$D$12))
